<?xml version="1.0" encoding="UTF-8"?>
<testng-results ignored="0" total="7" passed="1" failed="6" skipped="0">
  <reporter-output>
  </reporter-output>
  <suite started-at="2024-06-08T23:59:09 IST" name="Default suite" finished-at="2024-06-09T00:02:42 IST" duration-ms="212264">
    <groups>
    </groups>
    <test started-at="2024-06-08T23:59:09 IST" name="Default test" finished-at="2024-06-09T00:02:42 IST" duration-ms="212264">
      <class name="testcases.MyFirstTest">
        <test-method is-config="true" signature="setUp()[pri:0, instance:testcases.MyFirstTest@51399530]" started-at="2024-06-08T23:59:11 IST" name="setUp" finished-at="2024-06-08T23:59:30 IST" duration-ms="18322" status="PASS">
          <reporter-output>
          </reporter-output>
        </test-method> <!-- setUp -->
        <test-method signature="LoginTest(java.lang.String,java.lang.String)[pri:0, instance:testcases.MyFirstTest@51399530]" started-at="2024-06-08T23:59:30 IST" name="LoginTest" data-provider="LoginDataProvider" finished-at="2024-06-08T23:59:44 IST" duration-ms="13994" status="FAIL">
          <params>
            <param index="0">
              <value>
                <![CDATA[gfdsaghf@gail.com]]>
              </value>
            </param>
            <param index="1">
              <value>
                <![CDATA[dfdfdsf]]>
              </value>
            </param>
          </params>
          <exception class="java.lang.AssertionError">
            <message>
              <![CDATA[Test encountered an exception.]]>
            </message>
            <full-stacktrace>
              <![CDATA[java.lang.AssertionError: Test encountered an exception.
at org.testng.Assert.fail(Assert.java:111)
at testcases.MyFirstTest.LoginTest(MyFirstTest.java:56)
at java.base/jdk.internal.reflect.DirectMethodHandleAccessor.invoke(DirectMethodHandleAccessor.java:103)
at java.base/java.lang.reflect.Method.invoke(Method.java:580)
at org.testng.internal.invokers.MethodInvocationHelper.invokeMethod(MethodInvocationHelper.java:141)
at org.testng.internal.invokers.TestInvoker.invokeMethod(TestInvoker.java:686)
at org.testng.internal.invokers.TestInvoker.invokeTestMethod(TestInvoker.java:230)
at org.testng.internal.invokers.MethodRunner.runInSequence(MethodRunner.java:63)
at org.testng.internal.invokers.TestInvoker$MethodInvocationAgent.invoke(TestInvoker.java:992)
at org.testng.internal.invokers.TestInvoker.invokeTestMethods(TestInvoker.java:203)
at org.testng.internal.invokers.TestMethodWorker.invokeTestMethods(TestMethodWorker.java:154)
at org.testng.internal.invokers.TestMethodWorker.run(TestMethodWorker.java:134)
at java.base/java.util.ArrayList.forEach(ArrayList.java:1596)
at org.testng.TestRunner.privateRun(TestRunner.java:739)
at org.testng.TestRunner.run(TestRunner.java:614)
at org.testng.SuiteRunner.runTest(SuiteRunner.java:421)
at org.testng.SuiteRunner.runSequentially(SuiteRunner.java:413)
at org.testng.SuiteRunner.privateRun(SuiteRunner.java:373)
at org.testng.SuiteRunner.run(SuiteRunner.java:312)
at org.testng.SuiteRunnerWorker.runSuite(SuiteRunnerWorker.java:52)
at org.testng.SuiteRunnerWorker.run(SuiteRunnerWorker.java:95)
at org.testng.TestNG.runSuitesSequentially(TestNG.java:1274)
at org.testng.TestNG.runSuitesLocally(TestNG.java:1208)
at org.testng.TestNG.runSuites(TestNG.java:1112)
at org.testng.TestNG.run(TestNG.java:1079)
at org.testng.remote.AbstractRemoteTestNG.run(AbstractRemoteTestNG.java:115)
at org.testng.remote.RemoteTestNG.initAndRun(RemoteTestNG.java:293)
at org.testng.remote.RemoteTestNG.main(RemoteTestNG.java:91)
]]>
            </full-stacktrace>
          </exception> <!-- java.lang.AssertionError -->
          <reporter-output>
          </reporter-output>
        </test-method> <!-- LoginTest -->
        <test-method is-config="true" signature="tearDown()[pri:0, instance:testcases.MyFirstTest@51399530]" started-at="2024-06-08T23:59:44 IST" name="tearDown" finished-at="2024-06-08T23:59:46 IST" duration-ms="2128" status="PASS">
          <reporter-output>
          </reporter-output>
        </test-method> <!-- tearDown -->
        <test-method is-config="true" signature="setUp()[pri:0, instance:testcases.MyFirstTest@51399530]" started-at="2024-06-08T23:59:46 IST" name="setUp" finished-at="2024-06-09T00:00:06 IST" duration-ms="20375" status="PASS">
          <reporter-output>
          </reporter-output>
        </test-method> <!-- setUp -->
        <test-method signature="LoginTest(java.lang.String,java.lang.String)[pri:0, instance:testcases.MyFirstTest@51399530]" started-at="2024-06-09T00:00:06 IST" name="LoginTest" data-provider="LoginDataProvider" finished-at="2024-06-09T00:00:21 IST" duration-ms="14426" status="FAIL">
          <params>
            <param index="0">
              <value>
                <![CDATA[daffadsf@gmail.comvasdgasgasd]]>
              </value>
            </param>
            <param index="1">
              <value>
                <![CDATA[dsdasddf]]>
              </value>
            </param>
          </params>
          <exception class="java.lang.AssertionError">
            <message>
              <![CDATA[Test encountered an exception.]]>
            </message>
            <full-stacktrace>
              <![CDATA[java.lang.AssertionError: Test encountered an exception.
at org.testng.Assert.fail(Assert.java:111)
at testcases.MyFirstTest.LoginTest(MyFirstTest.java:56)
at java.base/jdk.internal.reflect.DirectMethodHandleAccessor.invoke(DirectMethodHandleAccessor.java:103)
at java.base/java.lang.reflect.Method.invoke(Method.java:580)
at org.testng.internal.invokers.MethodInvocationHelper.invokeMethod(MethodInvocationHelper.java:141)
at org.testng.internal.invokers.TestInvoker.invokeMethod(TestInvoker.java:686)
at org.testng.internal.invokers.TestInvoker.invokeTestMethod(TestInvoker.java:230)
at org.testng.internal.invokers.MethodRunner.runInSequence(MethodRunner.java:63)
at org.testng.internal.invokers.TestInvoker$MethodInvocationAgent.invoke(TestInvoker.java:992)
at org.testng.internal.invokers.TestInvoker.invokeTestMethods(TestInvoker.java:203)
at org.testng.internal.invokers.TestMethodWorker.invokeTestMethods(TestMethodWorker.java:154)
at org.testng.internal.invokers.TestMethodWorker.run(TestMethodWorker.java:134)
at java.base/java.util.ArrayList.forEach(ArrayList.java:1596)
at org.testng.TestRunner.privateRun(TestRunner.java:739)
at org.testng.TestRunner.run(TestRunner.java:614)
at org.testng.SuiteRunner.runTest(SuiteRunner.java:421)
at org.testng.SuiteRunner.runSequentially(SuiteRunner.java:413)
at org.testng.SuiteRunner.privateRun(SuiteRunner.java:373)
at org.testng.SuiteRunner.run(SuiteRunner.java:312)
at org.testng.SuiteRunnerWorker.runSuite(SuiteRunnerWorker.java:52)
at org.testng.SuiteRunnerWorker.run(SuiteRunnerWorker.java:95)
at org.testng.TestNG.runSuitesSequentially(TestNG.java:1274)
at org.testng.TestNG.runSuitesLocally(TestNG.java:1208)
at org.testng.TestNG.runSuites(TestNG.java:1112)
at org.testng.TestNG.run(TestNG.java:1079)
at org.testng.remote.AbstractRemoteTestNG.run(AbstractRemoteTestNG.java:115)
at org.testng.remote.RemoteTestNG.initAndRun(RemoteTestNG.java:293)
at org.testng.remote.RemoteTestNG.main(RemoteTestNG.java:91)
]]>
            </full-stacktrace>
          </exception> <!-- java.lang.AssertionError -->
          <reporter-output>
          </reporter-output>
        </test-method> <!-- LoginTest -->
        <test-method is-config="true" signature="tearDown()[pri:0, instance:testcases.MyFirstTest@51399530]" started-at="2024-06-09T00:00:21 IST" name="tearDown" finished-at="2024-06-09T00:00:21 IST" duration-ms="207" status="PASS">
          <reporter-output>
          </reporter-output>
        </test-method> <!-- tearDown -->
        <test-method is-config="true" signature="setUp()[pri:0, instance:testcases.MyFirstTest@51399530]" started-at="2024-06-09T00:00:21 IST" name="setUp" finished-at="2024-06-09T00:00:35 IST" duration-ms="14449" status="PASS">
          <reporter-output>
          </reporter-output>
        </test-method> <!-- setUp -->
        <test-method signature="LoginTest(java.lang.String,java.lang.String)[pri:0, instance:testcases.MyFirstTest@51399530]" started-at="2024-06-09T00:00:35 IST" name="LoginTest" data-provider="LoginDataProvider" finished-at="2024-06-09T00:00:49 IST" duration-ms="13541" status="FAIL">
          <params>
            <param index="0">
              <value>
                <![CDATA[sdasdsdadasd@gmail.com]]>
              </value>
            </param>
            <param index="1">
              <value>
                <![CDATA[fsfasdfsf]]>
              </value>
            </param>
          </params>
          <exception class="java.lang.AssertionError">
            <message>
              <![CDATA[Test encountered an exception.]]>
            </message>
            <full-stacktrace>
              <![CDATA[java.lang.AssertionError: Test encountered an exception.
at org.testng.Assert.fail(Assert.java:111)
at testcases.MyFirstTest.LoginTest(MyFirstTest.java:56)
at java.base/jdk.internal.reflect.DirectMethodHandleAccessor.invoke(DirectMethodHandleAccessor.java:103)
at java.base/java.lang.reflect.Method.invoke(Method.java:580)
at org.testng.internal.invokers.MethodInvocationHelper.invokeMethod(MethodInvocationHelper.java:141)
at org.testng.internal.invokers.TestInvoker.invokeMethod(TestInvoker.java:686)
at org.testng.internal.invokers.TestInvoker.invokeTestMethod(TestInvoker.java:230)
at org.testng.internal.invokers.MethodRunner.runInSequence(MethodRunner.java:63)
at org.testng.internal.invokers.TestInvoker$MethodInvocationAgent.invoke(TestInvoker.java:992)
at org.testng.internal.invokers.TestInvoker.invokeTestMethods(TestInvoker.java:203)
at org.testng.internal.invokers.TestMethodWorker.invokeTestMethods(TestMethodWorker.java:154)
at org.testng.internal.invokers.TestMethodWorker.run(TestMethodWorker.java:134)
at java.base/java.util.ArrayList.forEach(ArrayList.java:1596)
at org.testng.TestRunner.privateRun(TestRunner.java:739)
at org.testng.TestRunner.run(TestRunner.java:614)
at org.testng.SuiteRunner.runTest(SuiteRunner.java:421)
at org.testng.SuiteRunner.runSequentially(SuiteRunner.java:413)
at org.testng.SuiteRunner.privateRun(SuiteRunner.java:373)
at org.testng.SuiteRunner.run(SuiteRunner.java:312)
at org.testng.SuiteRunnerWorker.runSuite(SuiteRunnerWorker.java:52)
at org.testng.SuiteRunnerWorker.run(SuiteRunnerWorker.java:95)
at org.testng.TestNG.runSuitesSequentially(TestNG.java:1274)
at org.testng.TestNG.runSuitesLocally(TestNG.java:1208)
at org.testng.TestNG.runSuites(TestNG.java:1112)
at org.testng.TestNG.run(TestNG.java:1079)
at org.testng.remote.AbstractRemoteTestNG.run(AbstractRemoteTestNG.java:115)
at org.testng.remote.RemoteTestNG.initAndRun(RemoteTestNG.java:293)
at org.testng.remote.RemoteTestNG.main(RemoteTestNG.java:91)
]]>
            </full-stacktrace>
          </exception> <!-- java.lang.AssertionError -->
          <reporter-output>
          </reporter-output>
        </test-method> <!-- LoginTest -->
        <test-method is-config="true" signature="tearDown()[pri:0, instance:testcases.MyFirstTest@51399530]" started-at="2024-06-09T00:00:49 IST" name="tearDown" finished-at="2024-06-09T00:00:49 IST" duration-ms="251" status="PASS">
          <reporter-output>
          </reporter-output>
        </test-method> <!-- tearDown -->
        <test-method is-config="true" signature="setUp()[pri:0, instance:testcases.MyFirstTest@51399530]" started-at="2024-06-09T00:00:49 IST" name="setUp" finished-at="2024-06-09T00:01:02 IST" duration-ms="12762" status="PASS">
          <reporter-output>
          </reporter-output>
        </test-method> <!-- setUp -->
        <test-method signature="LoginTest(java.lang.String,java.lang.String)[pri:0, instance:testcases.MyFirstTest@51399530]" started-at="2024-06-09T00:01:02 IST" name="LoginTest" data-provider="LoginDataProvider" finished-at="2024-06-09T00:01:16 IST" duration-ms="14471" status="FAIL">
          <params>
            <param index="0">
              <value>
                <![CDATA[fasfs@husd.io]]>
              </value>
            </param>
            <param index="1">
              <value>
                <![CDATA[sfdfvasfd]]>
              </value>
            </param>
          </params>
          <exception class="java.lang.AssertionError">
            <message>
              <![CDATA[Test encountered an exception.]]>
            </message>
            <full-stacktrace>
              <![CDATA[java.lang.AssertionError: Test encountered an exception.
at org.testng.Assert.fail(Assert.java:111)
at testcases.MyFirstTest.LoginTest(MyFirstTest.java:56)
at java.base/jdk.internal.reflect.DirectMethodHandleAccessor.invoke(DirectMethodHandleAccessor.java:103)
at java.base/java.lang.reflect.Method.invoke(Method.java:580)
at org.testng.internal.invokers.MethodInvocationHelper.invokeMethod(MethodInvocationHelper.java:141)
at org.testng.internal.invokers.TestInvoker.invokeMethod(TestInvoker.java:686)
at org.testng.internal.invokers.TestInvoker.invokeTestMethod(TestInvoker.java:230)
at org.testng.internal.invokers.MethodRunner.runInSequence(MethodRunner.java:63)
at org.testng.internal.invokers.TestInvoker$MethodInvocationAgent.invoke(TestInvoker.java:992)
at org.testng.internal.invokers.TestInvoker.invokeTestMethods(TestInvoker.java:203)
at org.testng.internal.invokers.TestMethodWorker.invokeTestMethods(TestMethodWorker.java:154)
at org.testng.internal.invokers.TestMethodWorker.run(TestMethodWorker.java:134)
at java.base/java.util.ArrayList.forEach(ArrayList.java:1596)
at org.testng.TestRunner.privateRun(TestRunner.java:739)
at org.testng.TestRunner.run(TestRunner.java:614)
at org.testng.SuiteRunner.runTest(SuiteRunner.java:421)
at org.testng.SuiteRunner.runSequentially(SuiteRunner.java:413)
at org.testng.SuiteRunner.privateRun(SuiteRunner.java:373)
at org.testng.SuiteRunner.run(SuiteRunner.java:312)
at org.testng.SuiteRunnerWorker.runSuite(SuiteRunnerWorker.java:52)
at org.testng.SuiteRunnerWorker.run(SuiteRunnerWorker.java:95)
at org.testng.TestNG.runSuitesSequentially(TestNG.java:1274)
at org.testng.TestNG.runSuitesLocally(TestNG.java:1208)
at org.testng.TestNG.runSuites(TestNG.java:1112)
at org.testng.TestNG.run(TestNG.java:1079)
at org.testng.remote.AbstractRemoteTestNG.run(AbstractRemoteTestNG.java:115)
at org.testng.remote.RemoteTestNG.initAndRun(RemoteTestNG.java:293)
at org.testng.remote.RemoteTestNG.main(RemoteTestNG.java:91)
]]>
            </full-stacktrace>
          </exception> <!-- java.lang.AssertionError -->
          <reporter-output>
          </reporter-output>
        </test-method> <!-- LoginTest -->
        <test-method is-config="true" signature="tearDown()[pri:0, instance:testcases.MyFirstTest@51399530]" started-at="2024-06-09T00:01:16 IST" name="tearDown" finished-at="2024-06-09T00:01:17 IST" duration-ms="302" status="PASS">
          <reporter-output>
          </reporter-output>
        </test-method> <!-- tearDown -->
        <test-method is-config="true" signature="setUp()[pri:0, instance:testcases.MyFirstTest@51399530]" started-at="2024-06-09T00:01:17 IST" name="setUp" finished-at="2024-06-09T00:01:28 IST" duration-ms="11670" status="PASS">
          <reporter-output>
          </reporter-output>
        </test-method> <!-- setUp -->
        <test-method signature="LoginTest(java.lang.String,java.lang.String)[pri:0, instance:testcases.MyFirstTest@51399530]" started-at="2024-06-09T00:01:28 IST" name="LoginTest" data-provider="LoginDataProvider" finished-at="2024-06-09T00:01:42 IST" duration-ms="13359" status="FAIL">
          <params>
            <param index="0">
              <value>
                <![CDATA[dsfsdfvs.bfajb@jk.]]>
              </value>
            </param>
            <param index="1">
              <value>
                <![CDATA[asdfsfa]]>
              </value>
            </param>
          </params>
          <exception class="java.lang.AssertionError">
            <message>
              <![CDATA[Test encountered an exception.]]>
            </message>
            <full-stacktrace>
              <![CDATA[java.lang.AssertionError: Test encountered an exception.
at org.testng.Assert.fail(Assert.java:111)
at testcases.MyFirstTest.LoginTest(MyFirstTest.java:56)
at java.base/jdk.internal.reflect.DirectMethodHandleAccessor.invoke(DirectMethodHandleAccessor.java:103)
at java.base/java.lang.reflect.Method.invoke(Method.java:580)
at org.testng.internal.invokers.MethodInvocationHelper.invokeMethod(MethodInvocationHelper.java:141)
at org.testng.internal.invokers.TestInvoker.invokeMethod(TestInvoker.java:686)
at org.testng.internal.invokers.TestInvoker.invokeTestMethod(TestInvoker.java:230)
at org.testng.internal.invokers.MethodRunner.runInSequence(MethodRunner.java:63)
at org.testng.internal.invokers.TestInvoker$MethodInvocationAgent.invoke(TestInvoker.java:992)
at org.testng.internal.invokers.TestInvoker.invokeTestMethods(TestInvoker.java:203)
at org.testng.internal.invokers.TestMethodWorker.invokeTestMethods(TestMethodWorker.java:154)
at org.testng.internal.invokers.TestMethodWorker.run(TestMethodWorker.java:134)
at java.base/java.util.ArrayList.forEach(ArrayList.java:1596)
at org.testng.TestRunner.privateRun(TestRunner.java:739)
at org.testng.TestRunner.run(TestRunner.java:614)
at org.testng.SuiteRunner.runTest(SuiteRunner.java:421)
at org.testng.SuiteRunner.runSequentially(SuiteRunner.java:413)
at org.testng.SuiteRunner.privateRun(SuiteRunner.java:373)
at org.testng.SuiteRunner.run(SuiteRunner.java:312)
at org.testng.SuiteRunnerWorker.runSuite(SuiteRunnerWorker.java:52)
at org.testng.SuiteRunnerWorker.run(SuiteRunnerWorker.java:95)
at org.testng.TestNG.runSuitesSequentially(TestNG.java:1274)
at org.testng.TestNG.runSuitesLocally(TestNG.java:1208)
at org.testng.TestNG.runSuites(TestNG.java:1112)
at org.testng.TestNG.run(TestNG.java:1079)
at org.testng.remote.AbstractRemoteTestNG.run(AbstractRemoteTestNG.java:115)
at org.testng.remote.RemoteTestNG.initAndRun(RemoteTestNG.java:293)
at org.testng.remote.RemoteTestNG.main(RemoteTestNG.java:91)
]]>
            </full-stacktrace>
          </exception> <!-- java.lang.AssertionError -->
          <reporter-output>
          </reporter-output>
        </test-method> <!-- LoginTest -->
        <test-method is-config="true" signature="tearDown()[pri:0, instance:testcases.MyFirstTest@51399530]" started-at="2024-06-09T00:01:42 IST" name="tearDown" finished-at="2024-06-09T00:01:42 IST" duration-ms="261" status="PASS">
          <reporter-output>
          </reporter-output>
        </test-method> <!-- tearDown -->
        <test-method is-config="true" signature="setUp()[pri:0, instance:testcases.MyFirstTest@51399530]" started-at="2024-06-09T00:01:42 IST" name="setUp" finished-at="2024-06-09T00:01:56 IST" duration-ms="14402" status="PASS">
          <reporter-output>
          </reporter-output>
        </test-method> <!-- setUp -->
        <test-method signature="LoginTest(java.lang.String,java.lang.String)[pri:0, instance:testcases.MyFirstTest@51399530]" started-at="2024-06-09T00:01:56 IST" name="LoginTest" data-provider="LoginDataProvider" finished-at="2024-06-09T00:02:09 IST" duration-ms="12881" status="FAIL">
          <params>
            <param index="0">
              <value>
                <![CDATA[adsfsfv,irys.te]]>
              </value>
            </param>
            <param index="1">
              <value>
                <![CDATA[adsfadsvfsda]]>
              </value>
            </param>
          </params>
          <exception class="java.lang.AssertionError">
            <message>
              <![CDATA[Test encountered an exception.]]>
            </message>
            <full-stacktrace>
              <![CDATA[java.lang.AssertionError: Test encountered an exception.
at org.testng.Assert.fail(Assert.java:111)
at testcases.MyFirstTest.LoginTest(MyFirstTest.java:56)
at java.base/jdk.internal.reflect.DirectMethodHandleAccessor.invoke(DirectMethodHandleAccessor.java:103)
at java.base/java.lang.reflect.Method.invoke(Method.java:580)
at org.testng.internal.invokers.MethodInvocationHelper.invokeMethod(MethodInvocationHelper.java:141)
at org.testng.internal.invokers.TestInvoker.invokeMethod(TestInvoker.java:686)
at org.testng.internal.invokers.TestInvoker.invokeTestMethod(TestInvoker.java:230)
at org.testng.internal.invokers.MethodRunner.runInSequence(MethodRunner.java:63)
at org.testng.internal.invokers.TestInvoker$MethodInvocationAgent.invoke(TestInvoker.java:992)
at org.testng.internal.invokers.TestInvoker.invokeTestMethods(TestInvoker.java:203)
at org.testng.internal.invokers.TestMethodWorker.invokeTestMethods(TestMethodWorker.java:154)
at org.testng.internal.invokers.TestMethodWorker.run(TestMethodWorker.java:134)
at java.base/java.util.ArrayList.forEach(ArrayList.java:1596)
at org.testng.TestRunner.privateRun(TestRunner.java:739)
at org.testng.TestRunner.run(TestRunner.java:614)
at org.testng.SuiteRunner.runTest(SuiteRunner.java:421)
at org.testng.SuiteRunner.runSequentially(SuiteRunner.java:413)
at org.testng.SuiteRunner.privateRun(SuiteRunner.java:373)
at org.testng.SuiteRunner.run(SuiteRunner.java:312)
at org.testng.SuiteRunnerWorker.runSuite(SuiteRunnerWorker.java:52)
at org.testng.SuiteRunnerWorker.run(SuiteRunnerWorker.java:95)
at org.testng.TestNG.runSuitesSequentially(TestNG.java:1274)
at org.testng.TestNG.runSuitesLocally(TestNG.java:1208)
at org.testng.TestNG.runSuites(TestNG.java:1112)
at org.testng.TestNG.run(TestNG.java:1079)
at org.testng.remote.AbstractRemoteTestNG.run(AbstractRemoteTestNG.java:115)
at org.testng.remote.RemoteTestNG.initAndRun(RemoteTestNG.java:293)
at org.testng.remote.RemoteTestNG.main(RemoteTestNG.java:91)
]]>
            </full-stacktrace>
          </exception> <!-- java.lang.AssertionError -->
          <reporter-output>
          </reporter-output>
        </test-method> <!-- LoginTest -->
        <test-method is-config="true" signature="tearDown()[pri:0, instance:testcases.MyFirstTest@51399530]" started-at="2024-06-09T00:02:09 IST" name="tearDown" finished-at="2024-06-09T00:02:09 IST" duration-ms="192" status="PASS">
          <reporter-output>
          </reporter-output>
        </test-method> <!-- tearDown -->
        <test-method is-config="true" signature="setUp()[pri:0, instance:testcases.MyFirstTest@51399530]" started-at="2024-06-09T00:02:09 IST" name="setUp" finished-at="2024-06-09T00:02:36 IST" duration-ms="26732" status="PASS">
          <reporter-output>
          </reporter-output>
        </test-method> <!-- setUp -->
        <test-method signature="LoginTest(java.lang.String,java.lang.String)[pri:0, instance:testcases.MyFirstTest@51399530]" started-at="2024-06-09T00:02:36 IST" name="LoginTest" data-provider="LoginDataProvider" finished-at="2024-06-09T00:02:41 IST" duration-ms="5402" status="PASS">
          <params>
            <param index="0">
              <value>
                <![CDATA[dasunsooriyabandara@gmail.com]]>
              </value>
            </param>
            <param index="1">
              <value>
                <![CDATA[Test@2024]]>
              </value>
            </param>
          </params>
          <reporter-output>
          </reporter-output>
        </test-method> <!-- LoginTest -->
        <test-method is-config="true" signature="tearDown()[pri:0, instance:testcases.MyFirstTest@51399530]" started-at="2024-06-09T00:02:41 IST" name="tearDown" finished-at="2024-06-09T00:02:42 IST" duration-ms="173" status="PASS">
          <reporter-output>
          </reporter-output>
        </test-method> <!-- tearDown -->
      </class> <!-- testcases.MyFirstTest -->
    </test> <!-- Default test -->
  </suite> <!-- Default suite -->
</testng-results>
